Workbook

Sheet PM Dashboard
B3: FUEL SUBSIDY DASHBOARD | G3: LAST UPDATED
B4: Prime Minister's Office | G4: =IF('Processed by SBP'!G3<>"",TEXT('Processed by SBP'!G3,"DD-MMM-YYYY HH:MM")&" hrs",TEXT(NOW(),"DD-MMM-YYYY HH:MM")&" hrs") -> 07-Apr-2026 16:16 hrs
B7: RECEIVED FROM ALL ETOs | D7: SENT TO SBP | E7: RETURNED BY SBP | F7: BALANCE WITH SBP | G7: QTY PROCESSED BY SBP | H7: AMOUNT DISBURSED BY SBP | I7: QTY PENDING WITH SBP
B8: ='Recd from ETO'!D52 -> 127011 | D8: ='Sent to SBP'!D52 -> 127011 | E8: ='Returned by SBP'!C49 -> 460 | F8: =D8-E8-G8 -> 126551 | G8: ='Processed by SBP'!D50 -> 0 | H8: ='Processed by SBP'!F50 -> 0 | I8: =D8-G8 -> 127011
B9: ="CNIC: "&TEXT('Recd from ETO'!E52,"#,##0") -> CNIC: 113,989 | C9: ="NTN: "&TEXT('Recd from ETO'!F52,"#,##0") -> NTN: 13,022
B11: PROVINCE-WISE OVERVIEW
B12: Province | C12: Sent to SBP | D12: Returned by SBP | E12: Balance with SBP | F12: Qty Processed by SBP | G12: Amount Disbursed by SBP | H12: Pending with SBP
B13: Punjab | C13: ='Sent to SBP'!D10 -> 85834 | D13: ='Returned by SBP'!C7 -> 0 | E13: =C13-D13-F13 -> 85834 | F13: ='Processed by SBP'!D8 -> 0 | G13: ='Processed by SBP'!F8 -> 0 | H13: =C13-F13 -> 85834
B14: Sindh | C14: ='Sent to SBP'!D16 -> 0 | D14: ='Returned by SBP'!C13 -> 0 | E14: =C14-D14-F14 -> 0 | F14: ='Processed by SBP'!D14 -> 0 | G14: ='Processed by SBP'!F14 -> 0 | H14: =C14-F14 -> 0
B15: Balochistan | C15: ='Sent to SBP'!D22 -> 0 | D15: ='Returned by SBP'!C19 -> 460 | E15: =C15-D15-F15 -> -460 | F15: ='Processed by SBP'!D20 -> 0 | G15: ='Processed by SBP'!F20 -> 0 | H15: =C15-F15 -> 0
B16: KPK | C16: ='Sent to SBP'!D28 -> 0 | D16: ='Returned by SBP'!C25 -> 0 | E16: =C16-D16-F16 -> 0 | F16: ='Processed by SBP'!D26 -> 0 | G16: ='Processed by SBP'!F26 -> 0 | H16: =C16-F16 -> 0
B17: ICT | C17: ='Sent to SBP'!D34 -> 49 | D17: ='Returned by SBP'!C31 -> 0 | E17: =C17-D17-F17 -> 49 | F17: ='Processed by SBP'!D32 -> 0 | G17: ='Processed by SBP'!F32 -> 0 | H17: =C17-F17 -> 49
B18: AJK | C18: ='Sent to SBP'!D40 -> 995 | D18: ='Returned by SBP'!C37 -> 0 | E18: =C18-D18-F18 -> 995 | F18: ='Processed by SBP'!D38 -> 0 | G18: ='Processed by SBP'!F38 -> 0 | H18: =C18-F18 -> 995
B19: GB | C19: ='Sent to SBP'!D46 -> 18297 | D19: ='Returned by SBP'!C43 -> 0 | E19: =C19-D19-F19 -> 18297 | F19: ='Processed by SBP'!D44 -> 0 | G19: ='Processed by SBP'!F44 -> 0 | H19: =C19-F19 -> 18297
B20: TOTAL | C20: =SUM(C13:C19) -> 105175 | D20: =SUM(D13:D19) -> 460 | E20: =C20-D20-F20 -> 104715 | F20: =SUM(F13:F19) -> 0 | G20: =SUM(G13:G19) -> 0 | H20: =C20-F20 -> 105175
B22: VEHICLE TYPE BREAKDOWN
B23: Vehicle Type | C23: Sent to SBP | D23: Returned by SBP | E23: Balance with SBP | F23: Qty Processed by SBP | G23: Amount Disbursed by SBP | H23: Pending with SBP
B24: Truck | C24: ='Sent to SBP'!D47 -> 41472 | D24: ='Returned by SBP'!C44 -> 0 | E24: =C24-D24-F24 -> 41472 | F24: ='Processed by SBP'!D45 -> 0 | G24: ='Processed by SBP'!F45 -> 0 | H24: =C24-F24 -> 41472
B25: Long-Wheel Truck | C25: ='Sent to SBP'!D48 -> 2035 | D25: ='Returned by SBP'!C45 -> 0 | E25: =C25-D25-F25 -> 2035 | F25: ='Processed by SBP'!D46 -> 0 | G25: ='Processed by SBP'!F46 -> 0 | H25: =C25-F25 -> 2035
B26: Public Service Buses | C26: ='Sent to SBP'!D49 -> 5559 | D26: ='Returned by SBP'!C46 -> 460 | E26: =C26-D26-F26 -> 5099 | F26: ='Processed by SBP'!D47 -> 0 | G26: ='Processed by SBP'!F47 -> 0 | H26: =C26-F26 -> 5559
B27: Minibus/Wagon | C27: ='Sent to SBP'!D50 -> 12259 | D27: ='Returned by SBP'!C47 -> 0 | E27: =C27-D27-F27 -> 12259 | F27: ='Processed by SBP'!D48 -> 0 | G27: ='Processed by SBP'!F48 -> 0 | H27: =C27-F27 -> 12259
B28: Delivery Van/Loader | C28: ='Sent to SBP'!D51 -> 43850 | D28: ='Returned by SBP'!C48 -> 0 | E28: =C28-D28-F28 -> 43850 | F28: ='Processed by SBP'!D49 -> 0 | G28: ='Processed by SBP'!F49 -> 0 | H28: =C28-F28 -> 43850
B29: TOTAL | C29: =SUM(C24:C28) -> 105175 | D29: =SUM(D24:D28) -> 460 | E29: =C29-D29-F29 -> 104715 | F29: =SUM(F24:F28) -> 0 | G29: =SUM(G24:G28) -> 0 | H29: =C29-F29 -> 105175
B31: SBP PROCESSING PIPELINE BY PROVINCE

Sheet Recd from ETO
B2: Route Permit Data Received by PDA from ETO
D4: Total | E4: CNIC | F4: NTN | G4: Other | H4: Time Received
B5: Punjab | C5: Truck | D5: =SUM(E5,F5) -> 26952 | E5: 23833 | F5: 3119
C6: Long-Wheel Truck | D6: =SUM(E6,F6) -> 1342 | E6: 1252 | F6: 90
C7: Public Service Buses | D7: =SUM(E7,F7) -> 5364 | E7: 4124 | F7: 1240
C8: Minibus/Wagon | D8: =SUM(E8,F8) -> 10309 | E8: 9915 | F8: 394
C9: Delivery Van/Loader | D9: =SUM(E9,F9) -> 41867 | E9: 33690 | F9: 8177
C10: Total | D10: =SUM(E10,F10) -> 85834 | E10: 72814 | F10: 13020
B11: Sindh | C11: Truck | D11: =SUM(E11,F11) -> 0
C12: Long-Wheel Truck | D12: =SUM(E12,F12) -> 0
C13: Public Service Buses | D13: =SUM(E13,F13) -> 0
C14: Minibus/Wagon | D14: =SUM(E14,F14) -> 0
C15: Delivery Van/Loader | D15: =SUM(E15,F15) -> 0
C16: Total | D16: =SUM(E16,F16) -> 0
B17: Balochistan | C17: Truck | D17: =SUM(E17,F17) -> 0
C18: Long-Wheel Truck | D18: =SUM(E18,F18) -> 0
C19: Public Service Buses | D19: =SUM(E19,F19) -> 0
C20: Minibus/Wagon | D20: =SUM(E20,F20) -> 0
C21: Delivery Van/Loader | D21: =SUM(E21,F21) -> 0
C22: Total | D22: =SUM(E22,F22) -> 0
B23: KPK | C23: Truck | D23: =SUM(E23,F23) -> 11296 | E23: 11296
C24: Long-Wheel Truck | D24: =SUM(E24,F24) -> 46 | E24: 46
C25: Public Service Buses | D25: =SUM(E25,F25) -> 354 | E25: 354
C26: Minibus/Wagon | D26: =SUM(E26,F26) -> 3395 | E26: 3395
C27: Delivery Van/Loader | D27: =SUM(E27,F27) -> 16445 | E27: 16445
C28: Total | D28: =SUM(E28,F28) -> 31536 | E28: 31536
B29: ICT | C29: Truck | D29: =SUM(E29,F29) -> 0
C30: Long-Wheel Truck | D30: =SUM(E30,F30) -> 0
C31: Public Service Buses | D31: =SUM(E31,F31) -> 0
C32: Minibus/Wagon | D32: =SUM(E32,F32) -> 14 | E32: 13 | F32: 1
C33: Delivery Van/Loader | D33: =SUM(E33,F33) -> 35 | E33: 34 | F33: 1
C34: Total | D34: =SUM(E34,F34) -> 49 | E34: 47 | F34: 2
B35: AJK | C35: Truck | D35: =SUM(E35,F35) -> 781 | E35: 781 | F35: 0
C36: Long-Wheel Truck | D36: =SUM(E36,F36) -> 33 | E36: 33 | F36: 0
C37: Public Service Buses | D37: =SUM(E37,F37) -> 17 | E37: 17 | F37: 0
C38: Minibus/Wagon | D38: =SUM(E38,F38) -> 164 | E38: 164 | F38: 0
C39: Delivery Van/Loader | D39: =SUM(E39,F39) -> 0 | E39: 0 | F39: 0
C40: Total | D40: =SUM(E40,F40) -> 995 | E40: 995
B41: GB | C41: Truck | D41: =SUM(E41,F41) -> 7707 | E41: 7707 | F41: 0 | G41: 5882
C42: Long-Wheel Truck | D42: =SUM(E42,F42) -> 469 | E42: 469 | F42: 0 | G42: 191
...

Sheet Sent to SBP
B2: Sent to SBP
D4: Total | E4: CNIC | F4: NTN | G4: Other | H4: Time Received
B5: Punjab | C5: Truck | D5: 26952 | E5: 23833 | F5: 3119
C6: Long-Wheel Truck | D6: 1342 | E6: 1252 | F6: 90
C7: Public Service Buses | D7: 5364 | E7: 4124 | F7: 1240
C8: Minibus/Wagon | D8: 10309 | E8: 9915 | F8: 394
C9: Delivery Van/Loader | D9: 41867 | E9: 33690 | F9: 8177
C10: Total | D10: 85834 | E10: 72814 | F10: 13020
B11: Sindh | C11: Truck
C12: Long-Wheel Truck
C13: Public Service Buses
C14: Minibus/Wagon
C15: Delivery Van/Loader
C16: Total
B17: Balochistan | C17: Truck
C18: Long-Wheel Truck
C19: Public Service Buses
C20: Minibus/Wagon
C21: Delivery Van/Loader
C22: Total
B23: KPK | C23: Truck | E23: 11296
C24: Long-Wheel Truck | E24: 46
C25: Public Service Buses | E25: 354
C26: Minibus/Wagon | E26: 3395
C27: Delivery Van/Loader | E27: 16445
C28: Total | E28: 31536
B29: ICT | C29: Truck
C30: Long-Wheel Truck
C31: Public Service Buses
C32: Minibus/Wagon | D32: 14 | E32: 13 | F32: 1
C33: Delivery Van/Loader | D33: 35 | E33: 34 | F33: 1
C34: Total | D34: 49 | E34: 47 | F34: 2
B35: AJK | C35: Truck | D35: 781 | E35: 781 | F35: 0
C36: Long-Wheel Truck | D36: 33 | E36: 33 | F36: 0
C37: Public Service Buses | D37: 17 | E37: 17 | F37: 0
C38: Minibus/Wagon | D38: 164 | E38: 164 | F38: 0
C39: Delivery Van/Loader | D39: 0 | E39: 0 | F39: 0
C40: Total | D40: 995 | E40: 995
B41: GB | C41: Truck | D41: 13739 | E41: 7707 | F41: 0 | G41: 5882
C42: Long-Wheel Truck | D42: 660 | E42: 469 | F42: 0 | G42: 191
...

Sheet Returned by SBP
C1: Total
A2: Punjab | B2: Truck
B3: Long-Wheel Truck
B4: Public Service Buses
B5: Minibus/Wagon
B6: Delivery Van/Loader
B7: Total | C7: =SUM(C2:C6) -> 0
A8: Sindh | B8: Truck
B9: Long-Wheel Truck
B10: Public Service Buses
B11: Minibus/Wagon
B12: Delivery Van/Loader
B13: Total | C13: =SUM(C8:C12) -> 0
A14: Balochistan | B14: Truck
B15: Long-Wheel Truck
B16: Public Service Buses | C16: 460
B17: Minibus/Wagon
B18: Delivery Van/Loader
B19: Total | C19: =SUM(C14:C18 ) -> 460
A20: KPK | B20: Truck
B21: Long-Wheel Truck
B22: Public Service Buses
B23: Minibus/Wagon
B24: Delivery Van/Loader
B25: Total | C25: =SUM(C20:C24) -> 0
A26: ICT | B26: Truck
B27: Long-Wheel Truck
B28: Public Service Buses
B29: Minibus/Wagon
B30: Delivery Van/Loader
B31: Total | C31: =SUM(C26:C30) -> 0
A32: AJK | B32: Truck
B33: Long-Wheel Truck
B34: Public Service Buses
B35: Minibus/Wagon
B36: Delivery Van/Loader
B37: Total | C37: =SUM(C32:C36) -> 0
A38: GB | B38: Truck
B39: Long-Wheel Truck
B40: Public Service Buses
...

Sheet Processed by SBP
D2: Total Vehicles | E2: Unit Amount | F2: Total Amount Disbursed | G2: Time Updated
B3: Punjab | C3: Truck | F3: =D3*E3 -> 0
C4: Long-Wheel Truck | F4: =D4*E4 -> 0
C5: Public Service Buses | F5: =D5*E5 -> 0
C6: Minibus/Wagon | F6: =D6*E6 -> 0
C7: Delivery Van/Loader | F7: =D7*E7 -> 0
C8: Total | D8: =SUM(D3:D7) -> 0 | E8: =SUM(E3:E7) -> 0 | F8: =SUM(F3:F7) -> 0
B9: Sindh | C9: Truck | F9: =D9*E9 -> 0
C10: Long-Wheel Truck | F10: =D10*E10 -> 0
C11: Public Service Buses | F11: =D11*E11 -> 0
C12: Minibus/Wagon | F12: =D12*E12 -> 0
C13: Delivery Van/Loader | F13: =D13*E13 -> 0
C14: Total | D14: =SUM(D9:D13) -> 0 | E14: =SUM(E9:E13) -> 0 | F14: =SUM(F9:F13) -> 0
B15: Balochistan | C15: Truck | F15: =D15*E15 -> 0
C16: Long-Wheel Truck | F16: =D16*E16 -> 0
C17: Public Service Buses | F17: =D17*E17 -> 0
C18: Minibus/Wagon | F18: =D18*E18 -> 0
C19: Delivery Van/Loader | F19: =D19*E19 -> 0
C20: Total | D20: =SUM(D15:D19) -> 0 | E20: =SUM(E15:E19) -> 0 | F20: =SUM(F15:F19) -> 0
B21: KPK | C21: Truck | F21: =D21*E21 -> 0
C22: Long-Wheel Truck | F22: =D22*E22 -> 0
C23: Public Service Buses | F23: =D23*E23 -> 0
C24: Minibus/Wagon | F24: =D24*E24 -> 0
C25: Delivery Van/Loader | F25: =D25*E25 -> 0
C26: Total | D26: =SUM(D21:D25) -> 0 | E26: =SUM(E21:E25) -> 0 | F26: =SUM(F21:F25) -> 0
B27: ICT | C27: Truck | F27: =D27*E27 -> 0
C28: Long-Wheel Truck | F28: =D28*E28 -> 0
C29: Public Service Buses | F29: =D29*E29 -> 0
C30: Minibus/Wagon | F30: =D30*E30 -> 0
C31: Delivery Van/Loader | F31: =D31*E31 -> 0
C32: Total | D32: =SUM(D27:D31) -> 0 | E32: =SUM(E27:E31) -> 0 | F32: =SUM(F27:F31) -> 0
B33: AJK | C33: Truck | F33: =D33*E33 -> 0
C34: Long-Wheel Truck | F34: =D34*E34 -> 0
C35: Public Service Buses | F35: =D35*E35 -> 0
C36: Minibus/Wagon | F36: =D36*E36 -> 0
C37: Delivery Van/Loader | F37: =D37*E37 -> 0
C38: Total | D38: =SUM(D33:D37) -> 0 | E38: =SUM(E33:E37) -> 0 | F38: =SUM(F33:F37) -> 0
B39: GB | C39: Truck | F39: =D39*E39 -> 0
C40: Long-Wheel Truck | F40: =D40*E40 -> 0
C41: Public Service Buses | F41: =D41*E41 -> 0
...
